Traceback (most recent call last):
  File "/home/millen11/anaconda3/envs/autoPeft-cambridge/lib/python3.9/site-packages/huggingface_hub/utils/_errors.py", line 304, in hf_raise_for_status
    response.raise_for_status()
  File "/home/millen11/anaconda3/envs/autoPeft-cambridge/lib/python3.9/site-packages/requests/models.py", line 1024, in raise_for_status
    raise HTTPError(http_error_msg, response=self)
requests.exceptions.HTTPError: 403 Client Error: Forbidden for url: https://huggingface.co/namctin/patchtst_etth1_forecast/resolve/main/config.json

The above exception was the direct cause of the following exception:

Traceback (most recent call last):
  File "/home/millen11/anaconda3/envs/autoPeft-cambridge/lib/python3.9/site-packages/transformers/utils/hub.py", line 399, in cached_file
    resolved_file = hf_hub_download(
  File "/home/millen11/anaconda3/envs/autoPeft-cambridge/lib/python3.9/site-packages/huggingface_hub/utils/_validators.py", line 114, in _inner_fn
    return fn(*args, **kwargs)
  File "/home/millen11/anaconda3/envs/autoPeft-cambridge/lib/python3.9/site-packages/huggingface_hub/file_download.py", line 1221, in hf_hub_download
    return _hf_hub_download_to_cache_dir(
  File "/home/millen11/anaconda3/envs/autoPeft-cambridge/lib/python3.9/site-packages/huggingface_hub/file_download.py", line 1325, in _hf_hub_download_to_cache_dir
    _raise_on_head_call_error(head_call_error, force_download, local_files_only)
  File "/home/millen11/anaconda3/envs/autoPeft-cambridge/lib/python3.9/site-packages/huggingface_hub/file_download.py", line 1823, in _raise_on_head_call_error
    raise head_call_error
  File "/home/millen11/anaconda3/envs/autoPeft-cambridge/lib/python3.9/site-packages/huggingface_hub/file_download.py", line 1722, in _get_metadata_or_catch_error
    metadata = get_hf_file_metadata(url=url, proxies=proxies, timeout=etag_timeout, headers=headers)
  File "/home/millen11/anaconda3/envs/autoPeft-cambridge/lib/python3.9/site-packages/huggingface_hub/utils/_validators.py", line 114, in _inner_fn
    return fn(*args, **kwargs)
  File "/home/millen11/anaconda3/envs/autoPeft-cambridge/lib/python3.9/site-packages/huggingface_hub/file_download.py", line 1645, in get_hf_file_metadata
    r = _request_wrapper(
  File "/home/millen11/anaconda3/envs/autoPeft-cambridge/lib/python3.9/site-packages/huggingface_hub/file_download.py", line 372, in _request_wrapper
    response = _request_wrapper(
  File "/home/millen11/anaconda3/envs/autoPeft-cambridge/lib/python3.9/site-packages/huggingface_hub/file_download.py", line 396, in _request_wrapper
    hf_raise_for_status(response)
  File "/home/millen11/anaconda3/envs/autoPeft-cambridge/lib/python3.9/site-packages/huggingface_hub/utils/_errors.py", line 321, in hf_raise_for_status
    raise GatedRepoError(message, response) from e
huggingface_hub.utils._errors.GatedRepoError: 403 Client Error. (Request ID: Root=1-667db585-12631d48387461c953b8bf7f;bcb688e1-478f-444b-9fb1-327812c75b84)

Cannot access gated repo for url https://huggingface.co/namctin/patchtst_etth1_forecast/resolve/main/config.json.
Access to model ibm/testing-patchtst_etth1_forecast is restricted and you are not in the authorized list. Visit https://huggingface.co/ibm/testing-patchtst_etth1_forecast to ask for access.

The above exception was the direct cause of the following exception:

Traceback (most recent call last):
  File "/home/millen11/timeseries-fm-tuning/test.py", line 11, in <module>
    model = PatchTSTForPrediction.from_pretrained("namctin/patchtst_etth1_forecast")
  File "/home/millen11/anaconda3/envs/autoPeft-cambridge/lib/python3.9/site-packages/transformers/modeling_utils.py", line 3158, in from_pretrained
    config, model_kwargs = cls.config_class.from_pretrained(
  File "/home/millen11/anaconda3/envs/autoPeft-cambridge/lib/python3.9/site-packages/transformers/configuration_utils.py", line 603, in from_pretrained
    config_dict, kwargs = cls.get_config_dict(pretrained_model_name_or_path, **kwargs)
  File "/home/millen11/anaconda3/envs/autoPeft-cambridge/lib/python3.9/site-packages/transformers/configuration_utils.py", line 632, in get_config_dict
    config_dict, kwargs = cls._get_config_dict(pretrained_model_name_or_path, **kwargs)
  File "/home/millen11/anaconda3/envs/autoPeft-cambridge/lib/python3.9/site-packages/transformers/configuration_utils.py", line 689, in _get_config_dict
    resolved_config_file = cached_file(
  File "/home/millen11/anaconda3/envs/autoPeft-cambridge/lib/python3.9/site-packages/transformers/utils/hub.py", line 417, in cached_file
    raise EnvironmentError(
OSError: You are trying to access a gated repo.
Make sure to have access to it at https://huggingface.co/namctin/patchtst_etth1_forecast.
403 Client Error. (Request ID: Root=1-667db585-12631d48387461c953b8bf7f;bcb688e1-478f-444b-9fb1-327812c75b84)

Cannot access gated repo for url https://huggingface.co/namctin/patchtst_etth1_forecast/resolve/main/config.json.
Access to model ibm/testing-patchtst_etth1_forecast is restricted and you are not in the authorized list. Visit https://huggingface.co/ibm/testing-patchtst_etth1_forecast to ask for access.
